<?xml version="1.0"?>
<robot name="robot">
<link name="Torso">
    <visual>
      <origin xyz="0 0 0.275" rpy="0 0 0"/>
      <geometry>
        <box size="0.18 0.2 0.55"/>
      </geometry>
    </visual>
    <collision>
      <origin xyz="0 0 0.275" rpy="0 0 0"/>
      <geometry>
        <box size="0.18 0.2 0.55"/>
      </geometry>
    </collision>
    <visual>
      <origin xyz="0.085 0 0.02" rpy="0 0 0"/>
      <geometry>
        <box size="0.4 0.254 0.04"/>
      </geometry>
    </visual>
    <collision>
      <origin xyz="0.085 0 0.02" rpy="0 0 0"/>
      <geometry>
        <box size="0.4 0.254 0.04"/>
      </geometry>
    </collision>
    <visual>
      <origin xyz="0.001 0 0.05" rpy="0 0 0"/>
      <geometry>
        <box size="0.233 0.26 0.12"/>
      </geometry>
    </visual>
    <collision>
      <origin xyz="0.001 0 0.05" rpy="0 0 0"/>
      <geometry>
        <box size="0.233 0.26 0.12"/>
      </geometry>
    </collision>
  </link>
<link name="torso_lift_link">
    <visual>
      <origin xyz="0.164 0 0.317744" rpy="0 0 0"/>
      <geometry>
        <box size="0.15 0.138 0.074"/>
      </geometry>
    </visual>
    <collision>
      <origin xyz="0.164 0 0.317744" rpy="0 0 0"/>
      <geometry>
        <box size="0.15 0.138 0.074"/>
      </geometry>
    </collision>
    <visual>
      <origin xyz="0.1389 0 0.306544" rpy="0 -0.43 0"/>
      <geometry>
        <box size="0.12 0.134 0.097"/>
      </geometry>
    </visual>
    <collision>
      <origin xyz="0.1389 0 0.306544" rpy="0 -0.43 0"/>
      <geometry>
        <box size="0.12 0.134 0.097"/>
      </geometry>
    </collision>
    <visual>
      <origin xyz="-0.016 0 0.299744" rpy="0 0 0"/>
      <geometry>
        <box size="0.291 0.333 0.11"/>
      </geometry>
    </visual>
    <collision>
      <origin xyz="-0.016 0 0.299744" rpy="0 0 0"/>
      <geometry>
        <box size="0.291 0.333 0.11"/>
      </geometry>
    </collision>
    <visual>
      <origin xyz="0.003 0 0.066744" rpy="0 0 0"/>
      <geometry>
        <box size="0.228 0.263 0.358"/>
      </geometry>
    </visual>
    <collision>
      <origin xyz="0.003 0 0.066744" rpy="0 0 0"/>
      <geometry>
        <box size="0.228 0.263 0.358"/>
      </geometry>
    </collision>
  </link>
<link name="head_1_link">
    <visual>
      <origin xyz="0.01 0 0.097" rpy="-1.5708 0 0"/>
      <geometry>
        <cylinder radius="0.082" length="0.09"/>
      </geometry>
    </visual>
    <collision>
      <origin xyz="0.01 0 0.097" rpy="-1.5708 0 0"/>
      <geometry>
        <cylinder radius="0.082" length="0.09"/>
      </geometry>
    </collision>
    <visual>
      <origin xyz="-0.005 0 0.005" rpy="0 0 0"/>
      <geometry>
        <box size="0.103 0.088 0.103"/>
      </geometry>
    </visual>
    <collision>
      <origin xyz="-0.005 0 0.005" rpy="0 0 0"/>
      <geometry>
        <box size="0.103 0.088 0.103"/>
      </geometry>
    </collision>
  </link>
<link name="head_2_link">
    <visual>
      <origin xyz="-0.009 0.0466 0" rpy="0 0 -0.7"/>
      <geometry>
        <box size="0.092 0.132 0.26"/>
      </geometry>
    </visual>
    <collision>
      <origin xyz="-0.009 0.0466 0" rpy="0 0 -0.7"/>
      <geometry>
        <box size="0.092 0.132 0.26"/>
      </geometry>
    </collision>
    <visual>
      <origin xyz="0.008 -0.019 0" rpy="0 0 -1.5708"/>
      <geometry>
        <cylinder radius="0.03" length="0.132"/>
      </geometry>
    </visual>
    <collision>
      <origin xyz="0.008 -0.019 0" rpy="0 0 -1.5708"/>
      <geometry>
        <cylinder radius="0.03" length="0.132"/>
      </geometry>
    </collision>
    <visual>
      <origin xyz="0.054 0.06 0" rpy="0 0 0"/>
      <geometry>
        <box size="0.111 0.13 0.16"/>
      </geometry>
    </visual>
    <collision>
      <origin xyz="0.054 0.06 0" rpy="0 0 0"/>
      <geometry>
        <box size="0.111 0.13 0.16"/>
      </geometry>
    </collision>
    <visual>
      <origin xyz="0.053 0.056 -0.068" rpy="3.141593 -1.570793 3.141593"/>
      <geometry>
        <cylinder radius="0.0667" length="0.111"/>
      </geometry>
    </visual>
    <collision>
      <origin xyz="0.053 0.056 -0.068" rpy="3.141593 -1.570793 3.141593"/>
      <geometry>
        <cylinder radius="0.0667" length="0.111"/>
      </geometry>
    </collision>
    <visual>
      <origin xyz="0.053 0.056 0.068" rpy="3.141593 -1.570793 3.141593"/>
      <geometry>
        <cylinder radius="0.0667" length="0.111"/>
      </geometry>
    </visual>
    <collision>
      <origin xyz="0.053 0.056 0.068" rpy="3.141593 -1.570793 3.141593"/>
      <geometry>
        <cylinder radius="0.0667" length="0.111"/>
      </geometry>
    </collision>
  </link>
<link name="TIAGo front arm">
    <visual>
      <origin xyz="0.026 0.14 -0.232" rpy="0 0 1.5708"/>
      <geometry>
        <box size="0.042 0.094 0.094"/>
      </geometry>
    </visual>
    <collision>
      <origin xyz="0.026 0.14 -0.232" rpy="0 0 1.5708"/>
      <geometry>
        <box size="0.042 0.094 0.094"/>
      </geometry>
    </collision>
    <visual>
      <origin xyz="0.0256 0.1868 -0.2661" rpy="0.261799 0 0"/>
      <geometry>
        <cylinder radius="0.053" length="0.016"/>
      </geometry>
    </visual>
    <collision>
      <origin xyz="0.0256 0.1868 -0.2661" rpy="0.261799 0 0"/>
      <geometry>
        <cylinder radius="0.053" length="0.016"/>
      </geometry>
    </collision>
    <visual>
      <origin xyz="0.026 0.19 -0.221" rpy="0 0 -1.5708"/>
      <geometry>
        <cylinder radius="0.053" length="0.075"/>
      </geometry>
    </visual>
    <collision>
      <origin xyz="0.026 0.19 -0.221" rpy="0 0 -1.5708"/>
      <geometry>
        <cylinder radius="0.053" length="0.075"/>
      </geometry>
    </collision>
  </link>
<link name="TIAGo front arm_3">
    <visual>
      <origin xyz="0.0001 -0.000001 0.002" rpy="0 0 1.5708"/>
      <geometry>
        <cylinder radius="0.0522" length="0.052"/>
      </geometry>
    </visual>
    <collision>
      <origin xyz="0.0001 -0.000001 0.002" rpy="0 0 1.5708"/>
      <geometry>
        <cylinder radius="0.0522" length="0.052"/>
      </geometry>
    </collision>
    <visual>
      <origin xyz="0.0331 0.000999 0.001" rpy="0 0 0"/>
      <geometry>
        <box size="0.08 0.1044 0.048"/>
      </geometry>
    </visual>
    <collision>
      <origin xyz="0.0331 0.000999 0.001" rpy="0 0 0"/>
      <geometry>
        <box size="0.08 0.1044 0.048"/>
      </geometry>
    </collision>
    <visual>
      <origin xyz="0.0721 0.028999 -0.023" rpy="0 0 0"/>
      <geometry>
        <box size="0.035 0.09 0.081"/>
      </geometry>
    </visual>
    <collision>
      <origin xyz="0.0721 0.028999 -0.023" rpy="0 0 0"/>
      <geometry>
        <box size="0.035 0.09 0.081"/>
      </geometry>
    </collision>
    <visual>
      <origin xyz="0.1251 0.052999 -0.042" rpy="1.5708 0 0"/>
      <geometry>
        <cylinder radius="0.053" length="0.069"/>
      </geometry>
    </visual>
    <collision>
      <origin xyz="0.1251 0.052999 -0.042" rpy="1.5708 0 0"/>
      <geometry>
        <cylinder radius="0.053" length="0.069"/>
      </geometry>
    </collision>
  </link>
<link name="arm_2_link">
    <visual>
      <origin xyz="0.056 0 -0.0005" rpy="3.141593 -1.570793 3.141593"/>
      <geometry>
        <cylinder radius="0.052" length="0.048"/>
      </geometry>
    </visual>
    <collision>
      <origin xyz="0.056 0 -0.0005" rpy="3.141593 -1.570793 3.141593"/>
      <geometry>
        <cylinder radius="0.052" length="0.048"/>
      </geometry>
    </collision>
    <visual>
      <origin xyz="0 0 0.0295" rpy="0 0 -1.5708"/>
      <geometry>
        <cylinder radius="0.053" length="0.057"/>
      </geometry>
    </visual>
    <collision>
      <origin xyz="0 0 0.0295" rpy="0 0 -1.5708"/>
      <geometry>
        <cylinder radius="0.053" length="0.057"/>
      </geometry>
    </collision>
  </link>
<link name="arm_3_link">
    <visual>
      <origin xyz="0 0 -0.1037" rpy="0 0 -1.5708"/>
      <geometry>
        <cylinder radius="0.053" length="0.23"/>
      </geometry>
    </visual>
    <collision>
      <origin xyz="0 0 -0.1037" rpy="0 0 -1.5708"/>
      <geometry>
        <cylinder radius="0.053" length="0.23"/>
      </geometry>
    </collision>
    <visual>
      <origin xyz="-0.0169 0.03 -0.2187" rpy="1.5708 0 0"/>
      <geometry>
        <cylinder radius="0.056" length="0.056"/>
      </geometry>
    </visual>
    <collision>
      <origin xyz="-0.0169 0.03 -0.2187" rpy="1.5708 0 0"/>
      <geometry>
        <cylinder radius="0.056" length="0.056"/>
      </geometry>
    </collision>
  </link>
<link name="arm_4_link">
    <visual>
      <origin xyz="0 0.001 -0.002" rpy="0 0 1.5708"/>
      <geometry>
        <cylinder radius="0.054" length="0.056"/>
      </geometry>
    </visual>
    <collision>
      <origin xyz="0 0.001 -0.002" rpy="0 0 1.5708"/>
      <geometry>
        <cylinder radius="0.054" length="0.056"/>
      </geometry>
    </collision>
    <visual>
      <origin xyz="-0.093 0.019 0.027" rpy="3.141593 1.570793 3.141593"/>
      <geometry>
        <cylinder radius="0.052" length="0.191"/>
      </geometry>
    </visual>
    <collision>
      <origin xyz="-0.093 0.019 0.027" rpy="3.141593 1.570793 3.141593"/>
      <geometry>
        <cylinder radius="0.052" length="0.191"/>
      </geometry>
    </collision>
  </link>
<link name="arm_5_link">
    <visual>
      <origin xyz="0 0 0.04" rpy="0 0 1.57"/>
      <geometry>
        <cylinder radius="0.063" length="0.062"/>
      </geometry>
    </visual>
    <collision>
      <origin xyz="0 0 0.04" rpy="0 0 1.57"/>
      <geometry>
        <cylinder radius="0.063" length="0.062"/>
      </geometry>
    </collision>
    <visual>
      <origin xyz="0 0 0.099" rpy="0 0 1.57"/>
      <geometry>
        <cylinder radius="0.057" length="0.06"/>
      </geometry>
    </visual>
    <collision>
      <origin xyz="0 0 0.099" rpy="0 0 1.57"/>
      <geometry>
        <cylinder radius="0.057" length="0.06"/>
      </geometry>
    </collision>
    <visual>
      <origin xyz="0 0 0.156" rpy="0 0 1.57"/>
      <geometry>
        <cylinder radius="0.053" length="0.06"/>
      </geometry>
    </visual>
    <collision>
      <origin xyz="0 0 0.156" rpy="0 0 1.57"/>
      <geometry>
        <cylinder radius="0.053" length="0.06"/>
      </geometry>
    </collision>
  </link>
<link name="arm_6_link">
    <visual>
      <origin xyz="0.0409 0 0" rpy="3.141593 1.570793 3.141593"/>
      <geometry>
        <cylinder radius="0.0226" length="0.013"/>
      </geometry>
    </visual>
    <collision>
      <origin xyz="0.0409 0 0" rpy="3.141593 1.570793 3.141593"/>
      <geometry>
        <cylinder radius="0.0226" length="0.013"/>
      </geometry>
    </collision>
  </link>
<link name="arm_7_link">
    <visual>
      <origin xyz="0 0 0.055" rpy="0 0 1.5708"/>
      <geometry>
        <cylinder radius="0.0225" length="0.0157"/>
      </geometry>
    </visual>
    <collision>
      <origin xyz="0 0 0.055" rpy="0 0 1.5708"/>
      <geometry>
        <cylinder radius="0.0225" length="0.0157"/>
      </geometry>
    </collision>
  </link>
<link name="front">
    <visual>
      <origin xyz="0 0 0" rpy="0 0 0"/>
      <geometry>
        <cylinder radius="0.0227" length="0.028"/>
      </geometry>
    </visual>
    <collision>
      <origin xyz="0 0 0" rpy="0 0 0"/>
      <geometry>
        <cylinder radius="0.0227" length="0.028"/>
      </geometry>
    </collision>
    <visual>
      <origin xyz="0.029 -0.01834 -0.046" rpy="0 0 0.59"/>
      <geometry>
        <box size="0.04 0.0217 0.105"/>
      </geometry>
    </visual>
    <collision>
      <origin xyz="0.029 -0.01834 -0.046" rpy="0 0 0.59"/>
      <geometry>
        <box size="0.04 0.0217 0.105"/>
      </geometry>
    </collision>
    <visual>
      <origin xyz="-0.029 0.01834 -0.046" rpy="0 0 0.59"/>
      <geometry>
        <box size="0.04 0.0217 0.105"/>
      </geometry>
    </visual>
    <collision>
      <origin xyz="-0.029 0.01834 -0.046" rpy="0 0 0.59"/>
      <geometry>
        <box size="0.04 0.0217 0.105"/>
      </geometry>
    </collision>
    <visual>
      <origin xyz="0.0172 0.0109 -0.046" rpy="3.141593 -1.570793 3.141593"/>
      <geometry>
        <box size="0.106 0.056 0.071"/>
      </geometry>
    </visual>
    <collision>
      <origin xyz="0.0172 0.0109 -0.046" rpy="3.141593 -1.570793 3.141593"/>
      <geometry>
        <box size="0.106 0.056 0.071"/>
      </geometry>
    </collision>
    <visual>
      <origin xyz="-0.0172 -0.0109 -0.046" rpy="3.141593 -1.570793 3.141593"/>
      <geometry>
        <box size="0.106 0.056 0.071"/>
      </geometry>
    </visual>
    <collision>
      <origin xyz="-0.0172 -0.0109 -0.046" rpy="3.141593 -1.570793 3.141593"/>
      <geometry>
        <box size="0.106 0.056 0.071"/>
      </geometry>
    </collision>
  </link>
<link name="gripper_right_finger_link">
    <visual>
      <origin xyz="0.049 0 -0.1741" rpy="0 0 0"/>
      <geometry>
        <box size="0.0076 0.05091 0.08982"/>
      </geometry>
    </visual>
    <collision>
      <origin xyz="0.049 0 -0.1741" rpy="0 0 0"/>
      <geometry>
        <box size="0.0076 0.05091 0.08982"/>
      </geometry>
    </collision>
    <visual>
      <origin xyz="0.0499 0.0153 -0.1208" rpy="0 0 0"/>
      <geometry>
        <box size="0.0055 0.0295 0.018"/>
      </geometry>
    </visual>
    <collision>
      <origin xyz="0.0499 0.0153 -0.1208" rpy="0 0 0"/>
      <geometry>
        <box size="0.0055 0.0295 0.018"/>
      </geometry>
    </collision>
    <visual>
      <origin xyz="0.0365 0.0156 -0.1048" rpy="0 0 0"/>
      <geometry>
        <box size="0.03213 0.02959 0.01487"/>
      </geometry>
    </visual>
    <collision>
      <origin xyz="0.0365 0.0156 -0.1048" rpy="0 0 0"/>
      <geometry>
        <box size="0.03213 0.02959 0.01487"/>
      </geometry>
    </collision>
  </link>
<link name="gripper_left_finger_link">
    <visual>
      <origin xyz="0.049 0.000004 -0.1741" rpy="0 0 0"/>
      <geometry>
        <box size="0.0076 0.05091 0.08982"/>
      </geometry>
    </visual>
    <collision>
      <origin xyz="0.049 0.000004 -0.1741" rpy="0 0 0"/>
      <geometry>
        <box size="0.0076 0.05091 0.08982"/>
      </geometry>
    </collision>
    <visual>
      <origin xyz="0.0499 0.015304 -0.1208" rpy="0 0 0"/>
      <geometry>
        <box size="0.0055 0.0295 0.018"/>
      </geometry>
    </visual>
    <collision>
      <origin xyz="0.0499 0.015304 -0.1208" rpy="0 0 0"/>
      <geometry>
        <box size="0.0055 0.0295 0.018"/>
      </geometry>
    </collision>
    <visual>
      <origin xyz="0.0365 0.015604 -0.1048" rpy="0 0 0"/>
      <geometry>
        <box size="0.03213 0.02959 0.01487"/>
      </geometry>
    </visual>
    <collision>
      <origin xyz="0.0365 0.015604 -0.1048" rpy="0 0 0"/>
      <geometry>
        <box size="0.03213 0.02959 0.01487"/>
      </geometry>
    </collision>
  </link>
<joint name="torso_lift_joint" type="prismatic">
    <parent link="Torso"/>
    <child link="torso_lift_link"/>
    <axis xyz="0 0 1"/>
    <origin xyz="0 0 0.6" rpy="0 0 0"/>
    <limit effort="2000" lower="0" upper="0.35" velocity="0.07"/>
  </joint>
<joint name="head_1_joint" type="revolute">
    <parent link="torso_lift_link"/>
    <child link="head_1_link"/>
    <axis xyz="0 0 1"/>
    <limit effort="5.197" lower="-1.24" upper="1.24" velocity="3"/>
    <origin xyz="0.182 0 0.349744" rpy="0 0 -0.000001"/>
  </joint>
<joint name="head_2_joint" type="revolute">
    <parent link="head_1_link"/>
    <child link="head_2_link"/>
    <axis xyz="0 0.000004 1"/>
    <limit effort="2.77" lower="-0.98" upper="0.79" velocity="3"/>
    <origin xyz="0.005 0 0.098" rpy="1.5708 0 0"/>
  </joint>
<joint name="arm_1_joint" type="revolute">
    <parent link="TIAGo front arm"/>
    <child link="TIAGo front arm_3"/>
    <axis xyz="0 0 1"/>
    <limit effort="43" lower="0.07" upper="2.68" velocity="1.95"/>
    <origin xyz="0.025 0.194 -0.16" rpy="0 0 0.009"/>
  </joint>
<joint name="arm_2_joint" type="revolute">
    <parent link="TIAGo front arm_3"/>
    <child link="arm_2_link"/>
    <axis xyz="0 0.000004 1"/>
    <limit effort="43" lower="-1.5" upper="1.02" velocity="1.95"/>
    <origin xyz="0.1251 0.019499 -0.042" rpy="1.5708 0.000032 0"/>
  </joint>
<joint name="arm_3_joint" type="revolute">
    <parent link="arm_2_link"/>
    <child link="arm_3_link"/>
    <axis xyz="-0.000078 -0.000095 1"/>
    <limit effort="26" lower="-3.46" upper="1.5" velocity="2.35"/>
    <origin xyz="0.0895 0 0" rpy="-1.570892 0.000055 1.570718"/>
  </joint>
<joint name="arm_4_joint" type="revolute">
    <parent link="arm_3_link"/>
    <child link="arm_4_link"/>
    <axis xyz="0.000003 -0.000003 1"/>
    <limit effort="26" lower="-0.32" upper="2.29" velocity="2.35"/>
    <origin xyz="-0.02 -0.027 -0.2197" rpy="-1.890009 -1.570787 0.319209"/>
  </joint>
<joint name="arm_5_joint" type="revolute">
    <parent link="arm_4_link"/>
    <child link="arm_5_link"/>
    <axis xyz="0.000004 0 1"/>
    <limit effort="3" lower="-2.07" upper="2.07" velocity="1.95"/>
    <origin xyz="-0.162 0.02 0.027" rpy="2.011049 -1.570788 -2.011049"/>
  </joint>
<joint name="arm_6_joint" type="revolute">
    <parent link="arm_5_link"/>
    <child link="arm_6_link"/>
    <axis xyz="0.000003 -0.000003 1"/>
    <limit effort="6.6" lower="-1.39" upper="1.39" velocity="1.76"/>
    <origin xyz="0 0 0.15" rpy="-1.5708 -0.180799 0.000003"/>
  </joint>
<joint name="arm_7_joint" type="revolute">
    <parent link="arm_6_link"/>
    <child link="arm_7_link"/>
    <axis xyz="-0.000003 0.000003 1"/>
    <limit effort="6.6" lower="-2.07" upper="2.07" velocity="1.76"/>
    <origin xyz="0 0 0" rpy="-0.785397 -1.570792 -2.356193"/>
  </joint>
<joint name="gripper_right_finger_joint" type="prismatic">
    <parent link="front"/>
    <child link="gripper_right_finger_link"/>
    <axis xyz="1 0 0"/>
    <origin xyz="0 0 0" rpy="0 0 0"/>
    <limit effort="16" lower="0" upper="0.045" velocity="0.05"/>
  </joint>
<joint name="gripper_left_finger_joint" type="prismatic">
    <parent link="front"/>
    <child link="gripper_left_finger_link"/>
    <axis xyz="1 0.000093 0"/>
    <origin xyz="0.045 0 0" rpy="0 0 3.1415"/>
    <limit effort="16" lower="0" upper="0.045" velocity="0.05"/>
  </joint>
</robot>
