<?xml version="1.0"?>
<robot name="Tiago">

  <link name="base_link"/>

  <joint name="base_link_Torso_joint" type="fixed">
    <parent link="base_link"/>
    <child link="Torso"/>
    <origin xyz="-0.054 0 0.287" rpy="0 0 0"/>
  </joint>

  <link name="Torso"/>

  <joint name="torso_lift_joint" type="fixed">
    <parent link="Torso"/>
    <child link="torso_lift_link"/>
    <axis xyz="0 0 1"/>
    <origin xyz="0 0 0.75" rpy="0 0 0"/>
    <limit effort="2000" lower="0" upper="0.35" velocity="0.07"/>
  </joint>

  <link name="torso_lift_link"/>

  <joint name="torso_lift_link_TIAGo front arm_joint" type="fixed">
    <parent link="torso_lift_link"/>
    <child link="TIAGo front arm"/>
    <origin xyz="-0.037 0.0388 0.0224" rpy="0 0 -1.5708"/>
  </joint>

  <link name="TIAGo front arm"/>

  <joint name="arm_1_joint" type="revolute">
    <parent link="TIAGo front arm"/>
    <child link="TIAGo front arm_3"/>
    <axis xyz="0 0 1"/>
    <limit effort="43" lower="0.07" upper="2.68" velocity="1.95"/>
    <origin xyz="0.025 0.194 -0.16" rpy="0 0 0.01"/>
  </joint>

  <link name="TIAGo front arm_3"/>

  <joint name="arm_2_joint" type="revolute">
    <parent link="TIAGo front arm_3"/>
    <child link="arm_2_link"/>
    <axis xyz="0 0 1"/>
    <limit effort="43" lower="-1.5" upper="1.02" velocity="1.95"/>
    <origin xyz="0.1251 0.019499 -0.042" rpy="1.5708 0 0"/>
  </joint>

  <link name="arm_2_link"/>

  <joint name="arm_3_joint" type="revolute">
    <parent link="arm_2_link"/>
    <child link="arm_3_link"/>
    <axis xyz="0 0 1"/>
    <limit effort="26" lower="-3.46" upper="1.5" velocity="2.35"/>
    <origin xyz="0.0895 0 0" rpy="-1.5708 0 1.5708"/>
  </joint>

  <link name="arm_3_link"/>

  <joint name="arm_4_joint" type="revolute">
    <parent link="arm_3_link"/>
    <child link="arm_4_link"/>
    <axis xyz="0 0 1"/>
    <limit effort="26" lower="-0.32" upper="2.29" velocity="2.35"/>
    <origin xyz="-0.02 -0.027 -0.2197" rpy="2.356193 -1.570792 2.356193"/>
  </joint>

  <link name="arm_4_link"/>

  <joint name="arm_5_joint" type="revolute">
    <parent link="arm_4_link"/>
    <child link="arm_5_link"/>
    <axis xyz="0 0 1"/>
    <limit effort="3" lower="-2.07" upper="2.07" velocity="1.95"/>
    <origin xyz="-0.162 0.02 0.027" rpy="3.141593 -1.570793 3.141593"/>
  </joint>

  <link name="arm_5_link"/>

  <joint name="arm_6_joint" type="revolute">
    <parent link="arm_5_link"/>
    <child link="arm_6_link"/>
    <axis xyz="0 0 1"/>
    <limit effort="6.6" lower="-1.39" upper="1.39" velocity="1.76"/>
    <origin xyz="0 0 0.15" rpy="2.356193 -1.570792 2.356193"/>
  </joint>

  <link name="arm_6_link"/>

  <joint name="arm_7_joint" type="revolute">
    <parent link="arm_6_link"/>
    <child link="arm_7_link"/>
    <axis xyz="0 0 1"/>
    <limit effort="6.6" lower="-2.07" upper="2.07" velocity="1.76"/>
    <origin xyz="0 0 0" rpy="1.570799 -0.000003 1.570799"/>
  </joint>

  <link name="arm_7_link"/>

  <joint name="arm_7_link_wrist_ft_tool_link_joint" type="fixed">
    <parent link="arm_7_link"/>
    <child link="wrist_ft_tool_link"/>
    <origin xyz="0 0 0.067725" rpy="2.356193 -1.570792 2.356193"/>
  </joint>

  <link name="wrist_ft_tool_link"/>

  <joint name="wrist_ft_tool_link_front_joint" type="fixed">
    <parent link="wrist_ft_tool_link"/>
    <child link="front"/>
    <origin xyz="0.016 0 0" rpy="-2.356193 1.570792 0.785393"/>
  </joint>

  <link name="front"/>

</robot>